Workbook

Sheet Mode d'emploi
A1: CAHIER DE RECETTE – SYGEP
A3: 1. Une feuille par module. Une ligne par cas de test.
A4: 2. Se connecter avec le compte indiqué (mot de passe de démonstration : password), suivre les étapes, comparer au résultat attendu.
A5: 3. Choisir le résultat dans la liste (Non testé / OK / KO / Bloqué / N/A), puis renseigner date, testeur et observations.
A6: 4. La feuille « Synthèse » se met à jour automatiquement. Les KO sont à reporter dans « Anomalies ».
A7: 5. Priorités : Critique = bloquant ; Majeur ; Mineur. Acceptation : 100 % des cas critiques OK.
A8: 6. La colonne « Pré-recette auto » donne le résultat de l'exécution automatique ; elle ne remplace pas votre test.
A10: COMPTES DE TEST
A11: ADM – admin@admin.com – Super administrateur
A12: DIR – directeur@sygep.test – Directeur
A13: CPT – comptable@sygep.test – Comptable matière principal
A14: SEC – secondaire@sygep.test – Comptable matière secondaire (CFP de Thiès)
... A18: AGT – agent@sygep.test – Agent / demandeur (CFP de Thiès)

Sheet Synthèse
A1: Module | B1: Total | C1: OK | D1: KO | E1: Bloqué | F1: N/A | G1: Non testé | H1: % OK | I1: Critiques non OK
A2: AUT – Connexion, comptes et sécurité d'accès | B2: =COUNTA('AUT'!$A$5:$A$14) | C2: =COUNTIF('AUT'!$I$5:$I$14,"OK") | D2: =COUNTIF('AUT'!$I$5:$I$14,"KO") | E2: =COUNTIF('AUT'!$I$5:$I$14,"Bloqué") | F2: =COUNTIF('AUT'!$I$5:$I$14,"N/A") | G2: =COUNTIF('AUT'!$I$5:$I$14,"Non testé") | H2: =IF(B2=0,0,C2/B2) | I2: =COUNTIFS('AUT'!$G$5:$G$14,"Critique",'AUT'!$I$5:$I$14,"<>OK",'AUT'!$I$5:$I$14,"<>N/A")
A3: USR – Utilisateurs, rôles et droits | B3: =COUNTA('USR'!$A$5:$A$18) | C3: =COUNTIF('USR'!$I$5:$I$18,"OK") | D3: =COUNTIF('USR'!$I$5:$I$18,"KO") | E3: =COUNTIF('USR'!$I$5:$I$18,"Bloqué") | F3: =COUNTIF('USR'!$I$5:$I$18,"N/A") | G3: =COUNTIF('USR'!$I$5:$I$18,"Non testé") | H3: =IF(B3=0,0,C3/B3) | I3: =COUNTIFS('USR'!$G$5:$G$18,"Critique",'USR'!$I$5:$I$18,"<>OK",'USR'!$I$5:$I$18,"<>N/A")
A4: REF – Référentiels (services, catégories, emplacements, fournisseurs, bons) | B4: =COUNTA('REF'!$A$5:$A$18) | C4: =COUNTIF('REF'!$I$5:$I$18,"OK") | D4: =COUNTIF('REF'!$I$5:$I$18,"KO") | E4: =COUNTIF('REF'!$I$5:$I$18,"Bloqué") | F4: =COUNTIF('REF'!$I$5:$I$18,"N/A") | G4: =COUNTIF('REF'!$I$5:$I$18,"Non testé") | H4: =IF(B4=0,0,C4/B4) | I4: =COUNTIFS('REF'!$G$5:$G$18,"Critique",'REF'!$I$5:$I$18,"<>OK",'REF'!$I$5:$I$18,"<>N/A")
A5: AGT – Agents | B5: =COUNTA('AGT'!$A$5:$A$10) | C5: =COUNTIF('AGT'!$I$5:$I$10,"OK") | D5: =COUNTIF('AGT'!$I$5:$I$10,"KO") | E5: =COUNTIF('AGT'!$I$5:$I$10,"Bloqué") | F5: =COUNTIF('AGT'!$I$5:$I$10,"N/A") | G5: =COUNTIF('AGT'!$I$5:$I$10,"Non testé") | H5: =IF(B5=0,0,C5/B5) | I5: =COUNTIFS('AGT'!$G$5:$G$10,"Critique",'AGT'!$I$5:$I$10,"<>OK",'AGT'!$I$5:$I$10,"<>N/A")
A6: MAT – Matières, étiquettes QR et scanner | B6: =COUNTA('MAT'!$A$5:$A$34) | C6: =COUNTIF('MAT'!$I$5:$I$34,"OK") | D6: =COUNTIF('MAT'!$I$5:$I$34,"KO") | E6: =COUNTIF('MAT'!$I$5:$I$34,"Bloqué") | F6: =COUNTIF('MAT'!$I$5:$I$34,"N/A") | G6: =COUNTIF('MAT'!$I$5:$I$34,"Non testé") | H6: =IF(B6=0,0,C6/B6) | I6: =COUNTIFS('MAT'!$G$5:$G$34,"Critique",'MAT'!$I$5:$I$34,"<>OK",'MAT'!$I$5:$I$34,"<>N/A")
A7: AFF – Affectations, restitutions et transferts | B7: =COUNTA('AFF'!$A$5:$A$29) | C7: =COUNTIF('AFF'!$I$5:$I$29,"OK") | D7: =COUNTIF('AFF'!$I$5:$I$29,"KO") | E7: =COUNTIF('AFF'!$I$5:$I$29,"Bloqué") | F7: =COUNTIF('AFF'!$I$5:$I$29,"N/A") | G7: =COUNTIF('AFF'!$I$5:$I$29,"Non testé") | H7: =IF(B7=0,0,C7/B7) | I7: =COUNTIFS('AFF'!$G$5:$G$29,"Critique",'AFF'!$I$5:$I$29,"<>OK",'AFF'!$I$5:$I$29,"<>N/A")
A8: INV – Inventaires | B8: =COUNTA('INV'!$A$5:$A$21) | C8: =COUNTIF('INV'!$I$5:$I$21,"OK") | D8: =COUNTIF('INV'!$I$5:$I$21,"KO") | E8: =COUNTIF('INV'!$I$5:$I$21,"Bloqué") | F8: =COUNTIF('INV'!$I$5:$I$21,"N/A") | G8: =COUNTIF('INV'!$I$5:$I$21,"Non testé") | H8: =IF(B8=0,0,C8/B8) | I8: =COUNTIFS('INV'!$G$5:$G$21,"Critique",'INV'!$I$5:$I$21,"<>OK",'INV'!$I$5:$I$21,"<>N/A")
A9: STK – Stock des consommables : articles et mouvements | B9: =COUNTA('STK'!$A$5:$A$27) | C9: =COUNTIF('STK'!$I$5:$I$27,"OK") | D9: =COUNTIF('STK'!$I$5:$I$27,"KO") | E9: =COUNTIF('STK'!$I$5:$I$27,"Bloqué") | F9: =COUNTIF('STK'!$I$5:$I$27,"N/A") | G9: =COUNTIF('STK'!$I$5:$I$27,"Non testé") | H9: =IF(B9=0,0,C9/B9) | I9: =COUNTIFS('STK'!$G$5:$G$27,"Critique",'STK'!$I$5:$I$27,"<>OK",'STK'!$I$5:$I$27,"<>N/A")
A10: BST – Bons d'entrée et de sortie du stock | B10: =COUNTA('BST'!$A$5:$A$23) | C10: =COUNTIF('BST'!$I$5:$I$23,"OK") | D10: =COUNTIF('BST'!$I$5:$I$23,"KO") | E10: =COUNTIF('BST'!$I$5:$I$23,"Bloqué") | F10: =COUNTIF('BST'!$I$5:$I$23,"N/A") | G10: =COUNTIF('BST'!$I$5:$I$23,"Non testé") | H10: =IF(B10=0,0,C10/B10) | I10: =COUNTIFS('BST'!$G$5:$G$23,"Critique",'BST'!$I$5:$I$23,"<>OK",'BST'!$I$5:$I$23,"<>N/A")
A11: INF – Infrastructures | B11: =COUNTA('INF'!$A$5:$A$18) | C11: =COUNTIF('INF'!$I$5:$I$18,"OK") | D11: =COUNTIF('INF'!$I$5:$I$18,"KO") | E11: =COUNTIF('INF'!$I$5:$I$18,"Bloqué") | F11: =COUNTIF('INF'!$I$5:$I$18,"N/A") | G11: =COUNTIF('INF'!$I$5:$I$18,"Non testé") | H11: =IF(B11=0,0,C11/B11) | I11: =COUNTIFS('INF'!$G$5:$G$18,"Critique",'INF'!$I$5:$I$18,"<>OK",'INF'!$I$5:$I$18,"<>N/A")
A12: PRJ – Projets, jalons, chefs de projet, intervenants et rapports | B12: =COUNTA('PRJ'!$A$5:$A$24) | C12: =COUNTIF('PRJ'!$I$5:$I$24,"OK") | D12: =COUNTIF('PRJ'!$I$5:$I$24,"KO") | E12: =COUNTIF('PRJ'!$I$5:$I$24,"Bloqué") | F12: =COUNTIF('PRJ'!$I$5:$I$24,"N/A") | G12: =COUNTIF('PRJ'!$I$5:$I$24,"Non testé") | H12: =IF(B12=0,0,C12/B12) | I12: =COUNTIFS('PRJ'!$G$5:$G$24,"Critique",'PRJ'!$I$5:$I$24,"<>OK",'PRJ'!$I$5:$I$24,"<>N/A")
A13: MNT – Demandes de maintenance (circuit complet) | B13: =COUNTA('MNT'!$A$5:$A$27) | C13: =COUNTIF('MNT'!$I$5:$I$27,"OK") | D13: =COUNTIF('MNT'!$I$5:$I$27,"KO") | E13: =COUNTIF('MNT'!$I$5:$I$27,"Bloqué") | F13: =COUNTIF('MNT'!$I$5:$I$27,"N/A") | G13: =COUNTIF('MNT'!$I$5:$I$27,"Non testé") | H13: =IF(B13=0,0,C13/B13) | I13: =COUNTIFS('MNT'!$G$5:$G$27,"Critique",'MNT'!$I$5:$I$27,"<>OK",'MNT'!$I$5:$I$27,"<>N/A")
A14: PRV – Maintenance préventive | B14: =COUNTA('PRV'!$A$5:$A$15) | C14: =COUNTIF('PRV'!$I$5:$I$15,"OK") | D14: =COUNTIF('PRV'!$I$5:$I$15,"KO") | E14: =COUNTIF('PRV'!$I$5:$I$15,"Bloqué") | F14: =COUNTIF('PRV'!$I$5:$I$15,"N/A") | G14: =COUNTIF('PRV'!$I$5:$I$15,"Non testé") | H14: =IF(B14=0,0,C14/B14) | I14: =COUNTIFS('PRV'!$G$5:$G$15,"Critique",'PRV'!$I$5:$I$15,"<>OK",'PRV'!$I$5:$I$15,"<>N/A")
A15: TCH – Tâches, étiquettes et calendrier | B15: =COUNTA('TCH'!$A$5:$A$12) | C15: =COUNTIF('TCH'!$I$5:$I$12,"OK") | D15: =COUNTIF('TCH'!$I$5:$I$12,"KO") | E15: =COUNTIF('TCH'!$I$5:$I$12,"Bloqué") | F15: =COUNTIF('TCH'!$I$5:$I$12,"N/A") | G15: =COUNTIF('TCH'!$I$5:$I$12,"Non testé") | H15: =IF(B15=0,0,C15/B15) | I15: =COUNTIFS('TCH'!$G$5:$G$12,"Critique",'TCH'!$I$5:$I$12,"<>OK",'TCH'!$I$5:$I$12,"<>N/A")
A16: RPT – Rapports périodiques | B16: =COUNTA('RPT'!$A$5:$A$11) | C16: =COUNTIF('RPT'!$I$5:$I$11,"OK") | D16: =COUNTIF('RPT'!$I$5:$I$11,"KO") | E16: =COUNTIF('RPT'!$I$5:$I$11,"Bloqué") | F16: =COUNTIF('RPT'!$I$5:$I$11,"N/A") | G16: =COUNTIF('RPT'!$I$5:$I$11,"Non testé") | H16: =IF(B16=0,0,C16/B16) | I16: =COUNTIFS('RPT'!$G$5:$G$11,"Critique",'RPT'!$I$5:$I$11,"<>OK",'RPT'!$I$5:$I$11,"<>N/A")
A17: NTF – Notifications | B17: =COUNTA('NTF'!$A$5:$A$13) | C17: =COUNTIF('NTF'!$I$5:$I$13,"OK") | D17: =COUNTIF('NTF'!$I$5:$I$13,"KO") | E17: =COUNTIF('NTF'!$I$5:$I$13,"Bloqué") | F17: =COUNTIF('NTF'!$I$5:$I$13,"N/A") | G17: =COUNTIF('NTF'!$I$5:$I$13,"Non testé") | H17: =IF(B17=0,0,C17/B17) | I17: =COUNTIFS('NTF'!$G$5:$G$13,"Critique",'NTF'!$I$5:$I$13,"<>OK",'NTF'!$I$5:$I$13,"<>N/A")
A18: DSH – Tableau de bord, listes et ergonomie | B18: =COUNTA('DSH'!$A$5:$A$17) | C18: =COUNTIF('DSH'!$I$5:$I$17,"OK") | D18: =COUNTIF('DSH'!$I$5:$I$17,"KO") | E18: =COUNTIF('DSH'!$I$5:$I$17,"Bloqué") | F18: =COUNTIF('DSH'!$I$5:$I$17,"N/A") | G18: =COUNTIF('DSH'!$I$5:$I$17,"Non testé") | H18: =IF(B18=0,0,C18/B18) | I18: =COUNTIFS('DSH'!$G$5:$G$17,"Critique",'DSH'!$I$5:$I$17,"<>OK",'DSH'!$I$5:$I$17,"<>N/A")
A19: PUB – Site public et page Contact | B19: =COUNTA('PUB'!$A$5:$A$11) | C19: =COUNTIF('PUB'!$I$5:$I$11,"OK") | D19: =COUNTIF('PUB'!$I$5:$I$11,"KO") | E19: =COUNTIF('PUB'!$I$5:$I$11,"Bloqué") | F19: =COUNTIF('PUB'!$I$5:$I$11,"N/A") | G19: =COUNTIF('PUB'!$I$5:$I$11,"Non testé") | H19: =IF(B19=0,0,C19/B19) | I19: =COUNTIFS('PUB'!$G$5:$G$11,"Critique",'PUB'!$I$5:$I$11,"<>OK",'PUB'!$I$5:$I$11,"<>N/A")
A20: SEC – Droits et isolation des données | B20: =COUNTA('SEC'!$A$5:$A$16) | C20: =COUNTIF('SEC'!$I$5:$I$16,"OK") | D20: =COUNTIF('SEC'!$I$5:$I$16,"KO") | E20: =COUNTIF('SEC'!$I$5:$I$16,"Bloqué") | F20: =COUNTIF('SEC'!$I$5:$I$16,"N/A") | G20: =COUNTIF('SEC'!$I$5:$I$16,"Non testé") | H20: =IF(B20=0,0,C20/B20) | I20: =COUNTIFS('SEC'!$G$5:$G$16,"Critique",'SEC'!$I$5:$I$16,"<>OK",'SEC'!$I$5:$I$16,"<>N/A")
A21: INS – Installation et exploitation | B21: =COUNTA('INS'!$A$5:$A$15) | C21: =COUNTIF('INS'!$I$5:$I$15,"OK") | D21: =COUNTIF('INS'!$I$5:$I$15,"KO") | E21: =COUNTIF('INS'!$I$5:$I$15,"Bloqué") | F21: =COUNTIF('INS'!$I$5:$I$15,"N/A") | G21: =COUNTIF('INS'!$I$5:$I$15,"Non testé") | H21: =IF(B21=0,0,C21/B21) | I21: =COUNTIFS('INS'!$G$5:$G$15,"Critique",'INS'!$I$5:$I$15,"<>OK",'INS'!$I$5:$I$15,"<>N/A")
A22: TOTAL | B22: =SUM(B2:B21) | C22: =SUM(C2:C21) | D22: =SUM(D2:D21) | E22: =SUM(E2:E21) | F22: =SUM(F2:F21) | G22: =SUM(G2:G21) | H22: =IF(B22=0,0,C22/B22) | I22: =SUM(I2:I21)

Sheet AUT
A1: AUT – Connexion, comptes et sécurité d'accès
A2: Vérifier qui peut entrer, avec quels droits, et que l'accès est correctement protégé.
A4: ID | B4: Test | C4: Compte | D4: Préconditions | E4: Étapes | F4: Résultat attendu | G4: Priorité | H4: Pré-recette auto | I4: Résultat | J4: Date | K4: Testeur | L4: Observations
A5: AUT-01 | B5: Connexion réussie | C5: ADM (admin@admin.com) | D5: Compte actif et approuvé | E5: 1. Ouvrir /login 2. Saisir admin@admin.com et le mot de passe 3. Valider | F5: Le tableau de bord s'affiche. Le nom « Admin » apparaît en haut à droite. | G5: Critique | H5: OK | I5: Non testé
A6: AUT-02 | B6: Mot de passe erroné | C6: ADM (admin@admin.com) | D6: — | E6: 1. Ouvrir /login 2. Saisir un bon e-mail et un mauvais mot de passe 3. Valider | F6: Un message d'erreur s'affiche ; l'utilisateur reste sur la page de connexion. | G6: Critique | H6: OK | I6: Non testé
A7: AUT-03 | B7: Compte non approuvé refusé | C7: ADM (admin@admin.com) | D7: Un utilisateur créé SANS cocher « Approuvé » | E7: 1. Se connecter avec ce compte | F7: La connexion est refusée avec un message indiquant que le compte doit être approuvé par un administrateur. | G7: Critique | H7: OK | I7: Non testé
A8: AUT-04 | B8: Inscription libre | C8: — | D8: Page /register accessible | E8: 1. Ouvrir /register 2. Créer un compte avec un nouvel e-mail 3. Tenter de se connecter avec | F8: Le compte est créé mais ne peut pas se connecter (non approuvé). Dans Utilisateurs, il porte le rôle « User ». | G8: Critique | H8: OK | I8: Non testé
A9: AUT-05 | B9: Approuver un compte inscrit | C9: ADM (admin@admin.com) | D9: Compte créé à l'étape AUT-04 | E9: 1. Utilisateurs > modifier le compte 2. Cocher « Approuvé » et enregistrer 3. Se connecter avec ce compte | F9: La connexion réussit. Le menu ne montre presque aucun module (droits très limités du rôle « User »). | G9: Majeur | H9: OK | I9: Non testé
A10: AUT-06 | B10: Déconnexion | C10: ADM (admin@admin.com) | D10: Connecté | E10: 1. Cliquer « Déconnexion » en bas du menu 2. Confirmer « Se déconnecter » | F10: Retour à la page de connexion. Le bouton Précédent du navigateur ne rouvre pas l'espace de gestion. | G10: Critique | H10: OK | I10: Non testé
A11: AUT-07 | B11: Page protégée sans connexion | C11: — | D11: Déconnecté | E11: 1. Saisir directement l'adresse /admin/assets | F11: Redirection vers la page de connexion. | G11: Critique | H11: OK | I11: Non testé
A12: AUT-08 | B12: Changer son mot de passe | C12: ADM (admin@admin.com) | D12: Droit « profil » présent | E12: 1. Menu du compte > Profil 2. Saisir l'ancien puis le nouveau mot de passe 3. Se déconnecter et se reconnecter avec le nouveau | F12: Le nouveau mot de passe est accepté ; l'ancien ne fonctionne plus. | G12: Majeur | H12: Manuel | I12: Non testé
A13: AUT-09 | B13: Mot de passe oublié | C13: — | D13: Courrier (MAIL_*) configuré | E13: 1. Sur /login, cliquer « mot de passe oublié » 2. Saisir un e-mail existant | F13: Un message de confirmation s'affiche et un courriel de réinitialisation est envoyé. | G13: Mineur | H13: Manuel | I13: Non testé
A14: AUT-10 | B14: Session de longue durée | C14: ADM (admin@admin.com) | D14: Connecté | E14: 1. Laisser la page ouverte au-delà de la durée de session (120 min par défaut) 2. Soumettre un formulaire | F14: Un message de page expirée (419) s'affiche proprement ; recharger la page permet de continuer. | G14: Mineur | H14: Manuel | I14: Non testé

Sheet USR
A1: USR – Utilisateurs, rôles et droits
A2: Vérifier la gestion des comptes et le fait que chaque profil ne voit que ce qui le concerne.
A4: ID | B4: Test | C4: Compte | D4: Préconditions | E4: Étapes | F4: Résultat attendu | G4: Priorité | H4: Pré-recette auto | I4: Résultat | J4: Date | K4: Testeur | L4: Observations
A5: USR-01 | B5: Créer un utilisateur valide | C5: ADM (admin@admin.com) | D5: Un service existe | E5: 1. Utilisateurs > Ajouter 2. Nom, e-mail unique, mot de passe, cocher « Approuvé », service, rôle « Agent / demandeur » 3. Enregistrer | F5: L'utilisateur apparaît dans la liste. Il peut se connecter. | G5: Critique | H5: OK | I5: Non testé
A6: USR-02 | B6: E-mail déjà utilisé | C6: ADM (admin@admin.com) | D6: Un utilisateur existe avec l'e-mail X | E6: 1. Créer un utilisateur avec le même e-mail X | F6: Refus avec un message sous le champ E-mail. | G6: Critique | H6: OK | I6: Non testé
A7: USR-03 | B7: Rôle local sans service | C7: ADM (admin@admin.com) | D7: — | E7: 1. Créer un utilisateur avec le rôle « Comptable matière secondaire » 2. Laisser le service vide 3. Enregistrer | F7: Refus : « Le service de rattachement est obligatoire pour ce rôle. » | G7: Critique | H7: OK | I7: Non testé
A8: USR-04 | B8: Rôle local sans service (modification) | C8: ADM (admin@admin.com) | D8: Un utilisateur au rôle « Agent / demandeur » avec service | E8: 1. Modifier l'utilisateur 2. Vider le service 3. Enregistrer | F8: Refus avec le même message. | G8: Majeur | H8: OK | I8: Non testé
A9: USR-05 | B9: Aucun rôle | C9: ADM (admin@admin.com) | D9: — | E9: 1. Créer un utilisateur sans choisir de rôle | F9: Refus (au moins un rôle est obligatoire). | G9: Majeur | H9: OK | I9: Non testé
A10: USR-06 | B10: Champs obligatoires signalés | C10: ADM (admin@admin.com) | D10: — | E10: 1. Ouvrir Utilisateurs > Ajouter | F10: Nom, e-mail, mot de passe et rôles portent l'astérisque rouge. | G10: Mineur | H10: OK | I10: Non testé
A11: USR-07 | B11: Modifier le rôle d'un utilisateur | C11: ADM (admin@admin.com) | D11: Utilisateur agent | E11: 1. Changer son rôle en « Comptable matière secondaire » 2. Se connecter avec ce compte | F11: Le menu et les droits correspondent au nouveau rôle. | G11: Majeur | H11: OK | I11: Non testé
A12: USR-08 | B12: La page Rôles s'affiche | C12: ADM (admin@admin.com) | D12: — | E12: 1. Rôles et autorisations > Rôles 2. Ouvrir un rôle (œil) puis sa modification | F12: La liste montre pour chaque rôle sa description et ses droits par domaine ; la fiche et le formulaire s'affichent sans erreur. (Échoue si le fichier PermissionCatalog.php est absent : voir Guide 10.1.) | G12: Critique | H12: KO – statut 500 (500 attendu tant que PermissionCatalog.php n'est pas versionné) | I12: Non testé
A13: USR-09 | B13: Modifier les droits d'un rôle | C13: ADM (admin@admin.com) | D13: Un rôle de test avec le droit « supprimer les matières » | E13: 1. Retirer ce droit du rôle 2. Se reconnecter avec un compte de ce rôle 3. Ouvrir la liste des matières | F13: L'icône de suppression n'apparaît plus. | G13: Majeur | H13: Manuel | I13: Non testé
A14: USR-10 | B14: Menu adapté au profil | C14: AGT (agent@sygep.test) | D14: Compte agent | E14: 1. Se connecter 2. Observer le menu | F14: Seuls les modules autorisés apparaissent (matières du service, demandes de maintenance…) ; pas de Rôles, Stock, Infrastructures, Projets. | G14: Critique | H14: OK | I14: Non testé
A15: USR-11 | B15: Accès direct interdit | C15: AGT (agent@sygep.test) | D15: Compte agent | E15: 1. Saisir l'adresse /admin/users ou /admin/stock-items | F15: Erreur 403 (accès interdit). | G15: Critique | H15: OK | I15: Non testé
A16: USR-12 | B16: Directeur en lecture seule | C16: DIR (directeur@sygep.test) | D16: — | E16: 1. Ouvrir Matières, Projets, Infrastructures | F16: Aucun bouton « Ajouter », « Modifier » ni « Supprimer » n'est proposé. | G16: Majeur | H16: OK | I16: Non testé
... A18: USR-14 | B18: Suppression d'un utilisateur | C18: ADM (admin@admin.com) | D18: Un utilisateur de test | E18: 1. Supprimer l'utilisateur (icône corbeille) 2. Confirmer | F18: Il disparaît de la liste. Ses actions passées restent dans l'historique. | G18: Mineur | H18: OK | I18: Non testé

Sheet REF
A1: REF – Référentiels (services, catégories, emplacements, fournisseurs, bons)
A2: Vérifier les listes de choix et les bons d'acquisition.
A4: ID | B4: Test | C4: Compte | D4: Préconditions | E4: Étapes | F4: Résultat attendu | G4: Priorité | H4: Pré-recette auto | I4: Résultat | J4: Date | K4: Testeur | L4: Observations
A5: REF-01 | B5: Créer un service | C5: CPT (comptable@sygep.test) | D5: Seul le comptable principal (ou le super administrateur) crée des services | E5: 1. Gestion Matières > Services > Ajouter 2. Nom : « Service test » 3. Enregistrer | F5: Le service apparaît dans la liste. | G5: Critique | H5: OK | I5: Non testé
A6: REF-02 | B6: Service sans nom | C6: CPT (comptable@sygep.test) | D6: — | E6: 1. Services > Ajouter 2. Laisser le nom vide 3. Enregistrer | F6: Refus avec message sous le champ Nom. | G6: Critique | H6: OK | I6: Non testé
A7: REF-03 | B7: Créer une catégorie | C7: MAT (matieres@sygep.test) | D7: — | E7: 1. Catégories > Ajouter 2. Nom : « Catégorie test » 3. Enregistrer | F7: La catégorie apparaît ; elle est proposée dans le formulaire des matières. | G7: Critique | H7: OK | I7: Non testé
A8: REF-04 | B8: Créer un emplacement | C8: MAT (matieres@sygep.test) | D8: — | E8: 1. Emplacements > Ajouter 2. Nom : « Salle test » 3. Enregistrer | F8: L'emplacement apparaît ; il est proposé dans le formulaire des matières. | G8: Critique | H8: OK | I8: Non testé
A9: REF-05 | B9: Statuts de matières en français | C9: MAT (matieres@sygep.test) | D9: Base installée avec les seeders | E9: 1. Statuts des matières | F9: Les cinq statuts existent : Disponible, Pas disponible, En panne, En réparation, Affecté. | G9: Critique | H9: OK | I9: Non testé
A10: REF-06 | B10: Créer un fournisseur | C10: MAT (matieres@sygep.test) | D10: — | E10: 1. Fournisseurs > Ajouter 2. Nom et contact 3. Enregistrer | F10: Le fournisseur apparaît dans la liste. | G10: Critique | H10: OK | I10: Non testé
A11: REF-07 | B11: Fournisseur sans contact | C11: MAT (matieres@sygep.test) | D11: — | E11: 1. Fournisseurs > Ajouter 2. Renseigner le nom seulement | F11: Refus : le contact est obligatoire. | G11: Majeur | H11: OK | I11: Non testé
A12: REF-08 | B12: Créer un bon valide | C12: MAT (matieres@sygep.test) | D12: — | E12: 1. Bons > Ajouter 2. Date d'émission, organisation, référence de commande, destinataire, « Bon », date de livraison 3. Enregistrer | F12: Le bon apparaît dans la liste avec le nombre de matières à 0. | G12: Critique | H12: OK | I12: Non testé
A13: REF-09 | B13: Référence de commande en double | C13: MAT (matieres@sygep.test) | D13: Un bon avec la référence R1 existe | E13: 1. Créer un second bon avec la référence R1 | F13: Refus : la référence est déjà utilisée. | G13: Critique | H13: OK | I13: Non testé
A14: REF-10 | B14: Même organisation, deux bons | C14: MAT (matieres@sygep.test) | D14: Un bon de l'organisation O existe | E14: 1. Créer un bon de la même organisation O avec une autre référence | F14: Accepté (une organisation peut avoir plusieurs bons). | G14: Critique | H14: OK | I14: Non testé
A15: REF-11 | B15: Livraison avant émission | C15: MAT (matieres@sygep.test) | D15: — | E15: 1. Créer un bon avec une date de livraison antérieure à la date d'émission | F15: Refus avec message sous la date de livraison. | G15: Majeur | H15: OK | I15: Non testé
A16: REF-12 | B16: Bon sans libellé « Bon » | C16: MAT (matieres@sygep.test) | D16: — | E16: 1. Créer un bon en laissant le champ « Bon » vide | F16: Refus (champ obligatoire). | G16: Majeur | H16: OK | I16: Non testé
... A18: REF-14 | B18: Modifier un bon | C18: MAT (matieres@sygep.test) | D18: Un bon existe | E18: 1. Modifier la date de livraison 2. Enregistrer | F18: La modification est enregistrée ; les mêmes règles s'appliquent. | G18: Mineur | H18: OK | I18: Non testé

Sheet AGT
A1: AGT – Agents
A2: Vérifier l'enregistrement des bénéficiaires du matériel.
A4: ID | B4: Test | C4: Compte | D4: Préconditions | E4: Étapes | F4: Résultat attendu | G4: Priorité | H4: Pré-recette auto | I4: Résultat | J4: Date | K4: Testeur | L4: Observations
A5: AGT-01 | B5: Créer un agent valide | C5: MAT (matieres@sygep.test) | D5: Un service existe | E5: 1. Agents > Ajouter 2. Nom, prénom, téléphone, service 3. Enregistrer | F5: L'agent apparaît dans la liste avec son service. | G5: Critique | H5: OK | I5: Non testé
A6: AGT-02 | B6: Champs obligatoires | C6: MAT (matieres@sygep.test) | D6: — | E6: 1. Agents > Ajouter 2. Laisser nom, prénom, téléphone et service vides 3. Enregistrer | F6: Refus ; chaque champ obligatoire affiche son message. Les libellés portent l'astérisque. | G6: Critique | H6: OK | I6: Non testé
A7: AGT-03 | B7: E-mail invalide | C7: MAT (matieres@sygep.test) | D7: — | E7: 1. Saisir « pas-un-mail » dans l'e-mail | F7: Refus avec message sous le champ. | G7: Majeur | H7: OK | I7: Non testé
A8: AGT-04 | B8: E-mail facultatif et non unique | C8: MAT (matieres@sygep.test) | D8: Un agent avec l'e-mail X existe | E8: 1. Créer un second agent avec le même e-mail X 2. Créer un troisième sans e-mail | F8: Les deux sont acceptés. | G8: Mineur | H8: OK | I8: Non testé
A9: AGT-05 | B9: Fiche d'un agent | C9: MAT (matieres@sygep.test) | D9: Un agent détient du matériel (ex. Moussa Ndiaye) | E9: 1. Agents > œil | F9: La fiche montre le matériel détenu et ses bons d'affectation en cours. | G9: Majeur | H9: OK | I9: Non testé
A10: AGT-06 | B10: Chiffres de la liste | C10: MAT (matieres@sygep.test) | D10: Jeu de démonstration | E10: 1. Agents | F10: Les cartes (agents, détenteurs de matériel, sans matériel, retours en retard) sont cohérentes avec la liste. | G10: Mineur | H10: Manuel | I10: Non testé

Sheet MAT
A1: MAT – Matières, étiquettes QR et scanner
A2: Vérifier l'enregistrement des biens durables, leur identification et leur historique.
A4: ID | B4: Test | C4: Compte | D4: Préconditions | E4: Étapes | F4: Résultat attendu | G4: Priorité | H4: Pré-recette auto | I4: Résultat | J4: Date | K4: Testeur | L4: Observations
A5: MAT-01 | B5: Créer une matière minimale | C5: MAT (matieres@sygep.test) | D5: Catégorie et emplacement existent | E5: 1. Matières > Ajouter 2. Catégorie, nom, laisser l'état « Disponible », localisation, date d'achat (aujourd'hui ou avant) 3. Enregistrer | F5: La matière apparaît dans la liste. Sa fiche montre un code SYGEP-MAT-xxxxxx et, dans l'historique, une ligne « création ». | G5: Critique | H5: OK | I5: Non testé
A6: MAT-02 | B6: État proposé à la création | C6: MAT (matieres@sygep.test) | D6: — | E6: 1. Matières > Ajouter 2. Ouvrir la liste « État » | F6: « Disponible » est présélectionné ; « Affecté » et « En réparation » ne sont pas proposés. | G6: Critique | H6: OK | I6: Non testé
A7: MAT-03 | B7: Date d'achat future | C7: MAT (matieres@sygep.test) | D7: — | E7: 1. Saisir une date d'achat de demain 2. Enregistrer | F7: Refus avec message sous la date. | G7: Majeur | H7: OK | I7: Non testé
A8: MAT-04 | B8: Mise en service avant l'achat | C8: MAT (matieres@sygep.test) | D8: — | E8: 1. Date d'achat 15/06, mise en service 01/06 (même année) 2. Enregistrer | F8: Refus avec message sous la date de mise en service. | G8: Majeur | H8: OK | I8: Non testé
A9: MAT-05 | B9: Numéro de série en double | C9: MAT (matieres@sygep.test) | D9: Une matière avec le numéro de série S1 existe | E9: 1. Créer une autre matière avec le numéro S1 | F9: Refus (numéro déjà utilisé). | G9: Critique | H9: OK | I9: Non testé
A10: MAT-06 | B10: Numéro de série vide accepté | C10: MAT (matieres@sygep.test) | D10: — | E10: 1. Créer deux matières sans numéro de série | F10: Les deux sont acceptées. | G10: Majeur | H10: OK | I10: Non testé
A11: MAT-07 | B11: Champs facultatifs | C11: MAT (matieres@sygep.test) | D11: — | E11: 1. Créer une matière sans type, sans modèle, sans fournisseur, sans bon | F11: Acceptée. Le tableau et la fiche n'affichent rien (ou un tiret) pour ces champs. | G11: Majeur | H11: OK | I11: Non testé
A12: MAT-08 | B12: Fournisseur et bon à choix unique | C12: MAT (matieres@sygep.test) | D12: — | E12: 1. Matières > Ajouter 2. Observer les listes Fournisseur et Bon | F12: Chaque liste ne permet de choisir qu'un seul élément ; pas de boutons « tout sélectionner ». | G12: Mineur | H12: OK | I12: Non testé
A13: MAT-09 | B13: Photo de la matière | C13: MAT (matieres@sygep.test) | D13: Une image de moins de 2 Mo | E13: 1. Glisser une image dans la zone Photos 2. Enregistrer 3. Ouvrir la fiche | F13: La photo est enregistrée et visible (lien « voir » dans la fiche). | G13: Majeur | H13: Manuel | I13: Non testé
A14: MAT-10 | B14: Photo trop lourde | C14: MAT (matieres@sygep.test) | D14: Une image de plus de 2 Mo | E14: 1. Glisser l'image dans la zone Photos | F14: L'image est refusée avec un message de taille maximale. | G14: Mineur | H14: Manuel | I14: Non testé
A15: MAT-11 | B15: Modifier une matière | C15: MAT (matieres@sygep.test) | D15: Une matière existe | E15: 1. Modifier : changer la localisation 2. Enregistrer 3. Ouvrir la fiche > Historique | F15: Une ligne « modification » apparaît avec la nouvelle localisation et l'auteur. | G15: Critique | H15: OK | I15: Non testé
A16: MAT-12 | B16: Fiche d'une matière | C16: MAT (matieres@sygep.test) | D16: — | E16: 1. Matières > œil | F16: Trois blocs : Situation actuelle, QR code, Historique. Le bouton Transférer n'est proposé que si la matière est détenue (affectée). | G16: Majeur | H16: OK | I16: Non testé
... A34: MAT-30 | B34: Photos et notes dans la fiche | C34: MAT (matieres@sygep.test) | D34: Matière avec photo et notes | E34: 1. Ouvrir la fiche | F34: Les photos, notes, modèle, fournisseur et bon sont affichés. | G34: Mineur | H34: Manuel | I34: Non testé

Sheet AFF
A1: AFF – Affectations, restitutions et transferts
A2: Vérifier la remise de matériel, le bon imprimé, les retours et les statuts qui en découlent.
A4: ID | B4: Test | C4: Compte | D4: Préconditions | E4: Étapes | F4: Résultat attendu | G4: Priorité | H4: Pré-recette auto | I4: Résultat | J4: Date | K4: Testeur | L4: Observations
A5: AFF-01 | B5: Dotation à un agent | C5: MAT (matieres@sygep.test) | D5: Une matière Disponible ; un agent | E5: 1. Affectations > Nouvelle affectation 2. Cocher la matière 3. Choisir l'agent ; type « Dotation » ; date du jour 4. Enregistrer | F5: Un bon AFF-AAAA-nnnn est créé. La matière passe à « Affecté » et l'agent apparaît comme détenteur. L'historique contient une ligne « affectation ». | G5: Critique | H5: OK | I5: Non testé
A6: AFF-02 | B6: Plusieurs matières, un seul bon | C6: MAT (matieres@sygep.test) | D6: Trois matières Disponibles | E6: 1. Cocher les trois matières 2. Choisir un agent 3. Enregistrer | F6: Un seul bon liste les trois matières ; la tuile « Matières affectées » augmente de 3. | G6: Critique | H6: OK | I6: Non testé
A7: AFF-03 | B7: Affectation à un service | C7: MAT (matieres@sygep.test) | D7: Une matière Disponible | E7: 1. Choisir « Aucun agent » et un service 2. Enregistrer | F7: Accepté : le bénéficiaire est le service. | G7: Majeur | H7: OK | I7: Non testé
A8: AFF-04 | B8: Aucun bénéficiaire | C8: MAT (matieres@sygep.test) | D8: — | E8: 1. Cocher une matière 2. Ne choisir ni agent ni service 3. Enregistrer | F8: Refus : « Choisissez un agent ou un service bénéficiaire. » | G8: Critique | H8: OK | I8: Non testé
A9: AFF-05 | B9: Service repris de l'agent | C9: MAT (matieres@sygep.test) | D9: — | E9: 1. Choisir un agent sans choisir de service | F9: Le champ Service indique « Service de l'agent » (rempli automatiquement) ; le bon porte le service de l'agent. | G9: Majeur | H9: OK | I9: Non testé
A10: AFF-06 | B10: Seules les matières disponibles sont proposées | C10: MAT (matieres@sygep.test) | D10: Des matières affectées et en panne existent | E10: 1. Ouvrir Nouvelle affectation | F10: Les matières « Affecté » et « En panne » n'apparaissent pas. S'il n'y en a aucune de disponible, un message l'indique. | G10: Critique | H10: OK | I10: Non testé
A11: AFF-07 | B11: Aucune matière cochée | C11: MAT (matieres@sygep.test) | D11: — | E11: 1. Choisir un agent mais ne cocher aucune matière 2. Enregistrer | F11: Refus : « Sélectionnez au moins une matière. » | G11: Critique | H11: OK | I11: Non testé
A12: AFF-08 | B12: Temporaire sans date de retour | C12: MAT (matieres@sygep.test) | D12: — | E12: 1. Type « Mise à disposition temporaire » 2. Laisser « Retour prévu » vide 3. Enregistrer | F12: Refus : date de retour prévue obligatoire pour ce type. | G12: Critique | H12: OK | I12: Non testé
A13: AFF-09 | B13: Dotation sans date de retour | C13: MAT (matieres@sygep.test) | D13: — | E13: 1. Type « Dotation » 2. Laisser « Retour prévu » vide | F13: Accepté. | G13: Majeur | H13: OK | I13: Non testé
A14: AFF-10 | B14: Retour avant l'affectation | C14: MAT (matieres@sygep.test) | D14: — | E14: 1. Date d'affectation 20/10, retour prévu 10/10 2. Enregistrer | F14: Refus : la date de retour doit suivre la date d'affectation. | G14: Majeur | H14: OK | I14: Non testé
A15: AFF-11 | B15: Bon imprimé | C15: MAT (matieres@sygep.test) | D15: Une affectation existe | E15: 1. Fiche de l'affectation > Imprimer le bon | F15: Le bon affiche : en-tête République, numéro et date, bénéficiaire, conditions, tableau des matières (code, désignation, catégorie, série, modèle), texte d'engagement, signatures « Remis par » / « Reçu par ». | G15: Critique | H15: OK | I15: Non testé
A16: AFF-12 | B16: Restitution partielle | C16: CPT (comptable@sygep.test) | D16: Affectation de 3 matières | E16: 1. Fiche > Restituer 2. Cocher une seule matière 3. État « Bon état », date du jour 4. Enregistrer | F16: La matière redevient Disponible, sans détenteur. L'affectation passe à « Partielle ». | G16: Critique | H16: OK | I16: Non testé
... A29: AFF-25 | B29: Impossible de transférer hors de son service | C29: SEC (secondaire@sygep.test) | D29: Une matière du CFP de Thiès ; un agent d'un AUTRE service | E29: 1. Tenter le transfert vers cet agent (ou saisir son identifiant) | F29: Impossible : l'agent d'un autre service n'est pas accessible (erreur 404) ; aucun bon n'est créé et la matière ne change pas de service. | G29: Critique | H29: OK | I29: Non testé

Sheet INV
A1: INV – Inventaires
A2: Vérifier les campagnes de contrôle physique, du démarrage au procès-verbal.
A4: ID | B4: Test | C4: Compte | D4: Préconditions | E4: Étapes | F4: Résultat attendu | G4: Priorité | H4: Pré-recette auto | I4: Résultat | J4: Date | K4: Testeur | L4: Observations
A5: INV-01 | B5: Créer une campagne sur tout le parc | C5: CPT (comptable@sygep.test) | D5: — | E5: 1. Inventaires > Ajouter 2. Nom seulement ; laisser emplacement, service et catégorie sur « Tous » 3. Enregistrer | F5: La campagne INV-AAAA-nn est créée « En préparation ». | G5: Critique | H5: OK | I5: Non testé
A6: INV-02 | B6: Campagne sans nom | C6: CPT (comptable@sygep.test) | D6: — | E6: 1. Ajouter une campagne sans nom | F6: Refus : « Donnez un nom à la campagne. » | G6: Majeur | H6: OK | I6: Non testé
A7: INV-03 | B7: Fin avant le début | C7: CPT (comptable@sygep.test) | D7: — | E7: 1. Début prévu 20/10, fin prévue 10/10 | F7: Refus : « La date de fin doit suivre la date de début. » | G7: Majeur | H7: OK | I7: Non testé
A8: INV-04 | B8: Démarrer avec un périmètre | C8: CPT (comptable@sygep.test) | D8: Campagne limitée au service « CFP de Thiès » | E8: 1. Cliquer « Démarrer la campagne » | F8: La campagne passe « En cours ». Le tableau liste exactement les matières du service, toutes « À contrôler ». | G8: Critique | H8: OK | I8: Non testé
A9: INV-05 | B9: Pointer à la main | C9: SEC (secondaire@sygep.test) | D9: Campagne en cours | E9: 1. Cliquer « Pointer » sur une matière | F9: La matière passe « Contrôlée » ; l'avancement augmente. | G9: Critique | H9: OK | I9: Non testé
A10: INV-06 | B10: Scanner une matière attendue | C10: SEC (secondaire@sygep.test) | D10: Campagne en cours | E10: 1. Scanner > saisir le code d'une matière attendue 2. État « Bon état » | F10: Message « Contrôlée : … » ; la matière est contrôlée. | G10: Critique | H10: Manuel | I10: Non testé
A11: INV-07 | B11: Lire deux fois la même matière | C11: SEC (secondaire@sygep.test) | D11: Matière déjà contrôlée | E11: 1. Saisir de nouveau son code | F11: Message « Déjà contrôlée » ; rien n'est doublé. | G11: Majeur | H11: OK | I11: Non testé
A12: INV-08 | B12: Matière hors périmètre | C12: SEC (secondaire@sygep.test) | D12: Une matière d'un autre emplacement ou service | E12: 1. Saisir son code dans le scanner | F12: Message « Hors périmètre, ajoutée à la campagne » ; elle apparaît dans l'onglet Écarts. | G12: Majeur | H12: OK | I12: Non testé
A13: INV-09 | B13: Code inconnu | C13: SEC (secondaire@sygep.test) | D13: — | E13: 1. Saisir un code inexistant | F13: Message « Code inconnu » ; aucune ligne créée. | G13: Mineur | H13: OK | I13: Non testé
A14: INV-10 | B14: Clôture réservée | C14: MAT (matieres@sygep.test) | D14: Campagne en cours | E14: 1. Se connecter en MAT (administrateur des matières) 2. Ouvrir la campagne | F14: Le bouton « Clôturer la campagne » n'est pas proposé (droit réservé au comptable principal). | G14: Critique | H14: OK | I14: Non testé
A15: INV-11 | B15: Clôturer : non vues = manquantes | C15: CPT (comptable@sygep.test) | D15: Campagne en cours avec des matières non contrôlées | E15: 1. Clôturer la campagne | F15: Les matières non contrôlées passent « Manquante ». La campagne est « Clôturée ». | G15: Critique | H15: OK | I15: Non testé
A16: INV-12 | B16: Clôture avec mise à jour des fiches | C16: CPT (comptable@sygep.test) | D16: Une matière contrôlée à un autre lieu que prévu ; une matière contrôlée « Hors service » | E16: 1. Clôturer avec « Mettre à jour les fiches » coché 2. Ouvrir les deux matières | F16: L'emplacement de la première est corrigé ; la seconde passe « En panne ». Chaque correction figure dans l'historique (« Mise à jour suite à l'inventaire … »). | G16: Critique | H16: OK | I16: Non testé
... A21: INV-17 | B21: Scanner d'inventaire : lieu et état | C21: SEC (secondaire@sygep.test) | D21: Campagne en cours | E21: 1. Ouvrir Scanner 2. Choisir « Hors service » et un lieu 3. Saisir un code | F21: La matière est contrôlée avec l'état « Hors service » et le lieu choisi. | G21: Majeur | H21: Manuel | I21: Non testé

Sheet STK
A1: STK – Stock des consommables : articles et mouvements
A2: Vérifier que le solde est toujours juste, justifié et protégé.
A4: ID | B4: Test | C4: Compte | D4: Préconditions | E4: Étapes | F4: Résultat attendu | G4: Priorité | H4: Pré-recette auto | I4: Résultat | J4: Date | K4: Testeur | L4: Observations
A5: STK-01 | B5: Créer un article avec stock initial | C5: MAT (matieres@sygep.test) | D5: — | E5: 1. Stock consommables > Articles en stock > Ajouter 2. Désignation « Article test », unité, seuil 5, quantité en stock aujourd'hui 20 3. Enregistrer | F5: L'article reçoit une référence ART-nnnn. Son solde est 20. Son historique contient un mouvement d'entrée « Stock initial ». | G5: Critique | H5: OK | I5: Non testé
A6: STK-02 | B6: Seuil d'alerte obligatoire | C6: MAT (matieres@sygep.test) | D6: — | E6: 1. Créer un article sans seuil d'alerte | F6: Refus (champ obligatoire, astérisque rouge). | G6: Majeur | H6: OK | I6: Non testé
A7: STK-03 | B7: Champs obligatoires de l'article | C7: MAT (matieres@sygep.test) | D7: — | E7: 1. Créer un article sans désignation ni unité | F7: Refus avec message sous chaque champ. | G7: Majeur | H7: OK | I7: Non testé
A8: STK-04 | B8: Fiche d'un article | C8: MAT (matieres@sygep.test) | D8: Article avec mouvements | E8: 1. Ouvrir la fiche de « Ramette papier A4 80 g » | F8: La fiche montre le solde, les entrées et sorties du mois, la consommation moyenne mensuelle, la couverture en jours et la liste des mouvements. | G8: Majeur | H8: OK | I8: Non testé
A9: STK-05 | B9: Entrée valide | C9: MAT (matieres@sygep.test) | D9: Article existant (solde S) | E9: 1. Mouvements de stock > Nouveau mouvement > Entrée 2. Article, quantité 10, date du jour 3. Enregistrer | F9: Message « … nouveau solde S+10 ». Le solde de l'article est S+10. Le mouvement est numéroté MVT-AAAA-nnnnn. | G9: Critique | H9: OK | I9: Non testé
A10: STK-06 | B10: Sortie valide | C10: MAT (matieres@sygep.test) | D10: Article avec solde ≥ 5 ; un service | E10: 1. Nouveau mouvement > Sortie 2. Article, quantité 5, service bénéficiaire 3. Enregistrer | F10: Le solde diminue de 5. Le mouvement indique le service bénéficiaire. | G10: Critique | H10: OK | I10: Non testé
A11: STK-07 | B11: Sortie sans bénéficiaire | C11: MAT (matieres@sygep.test) | D11: — | E11: 1. Sortie sans service ni agent | F11: Refus : « Indiquez le service bénéficiaire de la sortie (ou l'agent demandeur). » | G11: Critique | H11: OK | I11: Non testé
A12: STK-08 | B12: Sortie par un agent | C12: MAT (matieres@sygep.test) | D12: Un agent d'un service | E12: 1. Sortie en choisissant l'agent demandeur et en laissant le service vide | F12: Acceptée : le service de l'agent est repris comme bénéficiaire. | G12: Majeur | H12: OK | I12: Non testé
A13: STK-09 | B13: Sortie supérieure au stock | C13: MAT (matieres@sygep.test) | D13: Article avec solde 11 | E13: 1. Sortie de 50 | F13: Refus : « Stock insuffisant : il reste 11 … ». Le solde ne change pas. | G13: Critique | H13: OK | I13: Non testé
A14: STK-10 | B14: Quantité nulle | C14: MAT (matieres@sygep.test) | D14: — | E14: 1. Entrée ou sortie avec quantité 0 | F14: Refus : la quantité doit être supérieure à zéro. | G14: Majeur | H14: OK | I14: Non testé
A15: STK-11 | B15: Date future | C15: MAT (matieres@sygep.test) | D15: — | E15: 1. Mouvement daté de demain | F15: Refus : la date ne peut pas être dans le futur. | G15: Majeur | H15: OK | I15: Non testé
A16: STK-12 | B16: Ajustement après comptage | C16: CPT (comptable@sygep.test) | D16: Article avec solde 20 | E16: 1. Nouveau mouvement > Ajustement 2. Quantité comptée 18, observations « casse » 3. Enregistrer | F16: Le solde devient 18. Le mouvement affiche un écart de −2. | G16: Critique | H16: OK | I16: Non testé
... A27: STK-23 | B27: Modification d'un article | C27: MAT (matieres@sygep.test) | D27: Un article existe | E27: 1. Modifier l'article 2. Constater que « Quantité en stock aujourd'hui » n'est pas proposée | F27: La quantité n'est pas modifiable à la main (elle ne change que par des mouvements). | G27: Majeur | H27: OK | I27: Non testé

Sheet BST
A1: BST – Bons d'entrée et de sortie du stock
A2: Vérifier les bons multi-articles : exactitude, « tout ou rien », impression.
A4: ID | B4: Test | C4: Compte | D4: Préconditions | E4: Étapes | F4: Résultat attendu | G4: Priorité | H4: Pré-recette auto | I4: Résultat | J4: Date | K4: Testeur | L4: Observations
A5: BST-01 | B5: Bon d'entrée à deux lignes | C5: MAT (matieres@sygep.test) | D5: Deux articles existants ; un fournisseur | E5: 1. Bons de stock > Bon d'entrée 2. Date du jour, fournisseur, N° de pièce 3. Ajouter deux lignes : article A qté 20, article B qté 10 4. Enregistrer | F5: Un bon BE-AAAA-nnnn est créé avec 2 articles. Les soldes de A et B augmentent de 20 et 10. Deux mouvements sont rattachés au bon. | G5: Critique | H5: OK | I5: Non testé
A6: BST-02 | B6: Bon de sortie à deux lignes | C6: MAT (matieres@sygep.test) | D6: Mêmes articles avec stock suffisant | E6: 1. Bon de sortie 2. Service bénéficiaire, agent demandeur 3. Deux lignes : A qté 5, B qté 2 4. Enregistrer | F6: Un bon BS-AAAA-nnnn est créé. Les soldes de A et B diminuent de 5 et 2. | G6: Critique | H6: OK | I6: Non testé
A7: BST-03 | B7: Même article deux fois | C7: MAT (matieres@sygep.test) | D7: — | E7: 1. Ajouter deux lignes avec le même article | F7: Refus : « Cet article figure déjà sur le bon : regroupez les quantités sur une seule ligne. » | G7: Majeur | H7: OK | I7: Non testé
A8: BST-04 | B8: Tout ou rien | C8: MAT (matieres@sygep.test) | D8: Article A avec stock suffisant, article B avec stock faible | E8: 1. Bon de sortie avec A qté 1 et B qté supérieure à son stock 2. Enregistrer 3. Vérifier les soldes de A et B | F8: Refus avec le message « Stock insuffisant » affiché sur la ligne de B. AUCUN bon n'est créé et le solde de A n'a pas changé. | G8: Critique | H8: OK | I8: Non testé
A9: BST-05 | B9: Quantité nulle | C9: MAT (matieres@sygep.test) | D9: — | E9: 1. Ligne avec quantité 0 | F9: Refus : la quantité doit être supérieure à zéro. | G9: Majeur | H9: OK | I9: Non testé
A10: BST-06 | B10: Bon sans article | C10: MAT (matieres@sygep.test) | D10: — | E10: 1. Laisser la ligne sans article 2. Enregistrer | F10: Refus (l'article est obligatoire). | G10: Majeur | H10: OK | I10: Non testé
A11: BST-07 | B11: Sortie sans service | C11: MAT (matieres@sygep.test) | D11: — | E11: 1. Bon de sortie sans service bénéficiaire | F11: Refus : « Indiquez le service bénéficiaire du bon de sortie (ou l'agent demandeur). » | G11: Critique | H11: OK | I11: Non testé
A12: BST-08 | B12: Entrée périssable sans péremption | C12: MAT (matieres@sygep.test) | D12: Article périssable | E12: 1. Bon d'entrée avec cet article, sans date de péremption | F12: Refus : « Article périssable : indiquez la date de péremption du lot. » Rien n'est créé. | G12: Critique | H12: OK | I12: Non testé
A13: BST-09 | B13: Date future | C13: MAT (matieres@sygep.test) | D13: — | E13: 1. Bon daté de demain | F13: Refus : la date du bon ne peut pas être dans le futur. | G13: Majeur | H13: OK | I13: Non testé
A14: BST-10 | B14: Champs selon le type | C14: MAT (matieres@sygep.test) | D14: — | E14: 1. Alterner Bon d'entrée / Bon de sortie dans le formulaire | F14: En entrée : fournisseur, prix unitaire, péremption. En sortie : service et agent. Les autres champs sont masqués. | G14: Mineur | H14: OK | I14: Non testé
A15: BST-11 | B15: Choix d'un article | C15: MAT (matieres@sygep.test) | D15: — | E15: 1. Choisir un article dans une ligne | F15: L'unité et le stock actuel s'affichent sur la ligne. | G15: Mineur | H15: OK | I15: Non testé
A16: BST-12 | B16: Ajouter et retirer des lignes | C16: MAT (matieres@sygep.test) | D16: — | E16: 1. Cliquer « Ajouter un article » trois fois 2. Retirer une ligne avec la croix | F16: Les lignes s'ajoutent et se retirent ; on ne peut pas retirer la dernière. | G16: Mineur | H16: OK | I16: Non testé
... A23: BST-19 | B23: Numérotation | C23: MAT (matieres@sygep.test) | D23: Deux bons créés dans la même année | E23: 1. Créer deux bons de sortie | F23: Les numéros se suivent (BS-AAAA-0001, 0002…). | G23: Mineur | H23: OK | I23: Non testé

Sheet INF
A1: INF – Infrastructures
A2: Vérifier la hiérarchie, l'état et l'amortissement.
A4: ID | B4: Test | C4: Compte | D4: Préconditions | E4: Étapes | F4: Résultat attendu | G4: Priorité | H4: Pré-recette auto | I4: Résultat | J4: Date | K4: Testeur | L4: Observations
A5: INF-01 | B5: Créer une structure | C5: INF (infrastructures@sygep.test) | D5: — | E5: 1. Infrastructures > Ajouter 2. Nom, nature « Structure », situation « En service » 3. Enregistrer | F5: La structure apparaît dans la liste. | G5: Critique | H5: OK | I5: Non testé
A6: INF-02 | B6: Bâtiment rattaché à une structure | C6: INF (infrastructures@sygep.test) | D6: Une structure existe | E6: 1. Nature « Bâtiment », rattaché à la structure | F6: Accepté. | G6: Critique | H6: OK | I6: Non testé
A7: INF-03 | B7: Bloc rattaché à un bâtiment | C7: INF (infrastructures@sygep.test) | D7: Un bâtiment existe | E7: 1. Nature « Bloc », rattaché au bâtiment | F7: Accepté. | G7: Critique | H7: OK | I7: Non testé
A8: INF-04 | B8: Structure rattachée à autre chose | C8: INF (infrastructures@sygep.test) | D8: — | E8: 1. Nature « Structure », rattachée à un bâtiment | F8: Refus : « Une structure est un site principal : elle ne se rattache à rien. » | G8: Majeur | H8: OK | I8: Non testé
A9: INF-05 | B9: Bâtiment rattaché à un bloc | C9: INF (infrastructures@sygep.test) | D9: Un bloc existe | E9: 1. Nature « Bâtiment », rattaché à un bloc | F9: Refus : « Un bâtiment se rattache à une structure. » | G9: Majeur | H9: OK | I9: Non testé
A10: INF-06 | B10: Amortissement incomplet | C10: INF (infrastructures@sygep.test) | D10: — | E10: 1. Renseigner seulement la valeur d'origine 2. Enregistrer | F10: Refus : demande de la date de mise en service et de la durée, avec un message sous chaque champ manquant. | G10: Critique | H10: OK | I10: Non testé
A11: INF-07 | B11: Amortissement complet | C11: INF (infrastructures@sygep.test) | D11: — | E11: 1. Valeur 400 000 000, mise en service il y a 10 ans, durée 40 ans 2. Enregistrer 3. Ouvrir la fiche | F11: La fiche affiche l'annuité (10 000 000), la part amortie (≈ 25 %), la valeur nette (≈ 300 000 000) et le plan année par année. | G11: Critique | H11: OK | I11: Non testé
A12: INF-08 | B12: Sans valorisation | C12: INF (infrastructures@sygep.test) | D12: — | E12: 1. Laisser les trois champs d'amortissement vides | F12: Accepté ; aucun plan d'amortissement n'est affiché. | G12: Mineur | H12: OK | I12: Non testé
A13: INF-09 | B13: Visite future | C13: INF (infrastructures@sygep.test) | D13: — | E13: 1. Date de dernière visite de demain | F13: Refus. | G13: Mineur | H13: OK | I13: Non testé
A14: INF-10 | B14: Valeurs négatives | C14: INF (infrastructures@sygep.test) | D14: — | E14: 1. Surface −5 | F14: Refus. | G14: Mineur | H14: OK | I14: Non testé
A15: INF-11 | B15: Durée hors limites | C15: INF (infrastructures@sygep.test) | D15: — | E15: 1. Durée 0, puis 150 | F15: Refus (la durée va de 1 à 100 ans). | G15: Mineur | H15: OK | I15: Non testé
A16: INF-12 | B16: Fiche d'une infrastructure | C16: INF (infrastructures@sygep.test) | D16: Infrastructure avec projet et demande | E16: 1. Ouvrir la fiche | F16: La fiche montre les bâtiments/blocs rattachés, les projets liés, la maintenance, et le bouton « Signaler un problème ». | G16: Majeur | H16: OK | I16: Non testé
... A18: INF-14 | B18: Chiffres clés et état | C18: INF (infrastructures@sygep.test) | D18: Jeu de démonstration | E18: 1. Infrastructures | F18: Les chiffres clés (nombre, situation, état) sont cohérents avec la liste. | G18: Mineur | H18: Manuel | I18: Non testé

Sheet PRJ
A1: PRJ – Projets, jalons, chefs de projet, intervenants et rapports
A2: Vérifier le suivi des chantiers et le calcul automatique de l'avancement.
A4: ID | B4: Test | C4: Compte | D4: Préconditions | E4: Étapes | F4: Résultat attendu | G4: Priorité | H4: Pré-recette auto | I4: Résultat | J4: Date | K4: Testeur | L4: Observations
A5: PRJ-01 | B5: Créer un projet planifié | C5: INF (infrastructures@sygep.test) | D5: — | E5: 1. Projets > Ajouter 2. Intitulé, nature, statut « Planifié » 3. Enregistrer | F5: Le projet reçoit une référence PRJ-AAAA-nn. Message d'invitation à ajouter des jalons. | G5: Critique | H5: OK | I5: Non testé
A6: PRJ-02 | B6: Projet lancé sans date de démarrage | C6: INF (infrastructures@sygep.test) | D6: — | E6: 1. Statut « En cours », date de démarrage vide 2. Enregistrer | F6: Refus : « Indiquez la date de démarrage : le projet est déjà lancé. » | G6: Critique | H6: OK | I6: Non testé
A7: PRJ-03 | B7: Fin avant démarrage | C7: INF (infrastructures@sygep.test) | D7: — | E7: 1. Démarrage 20/10, fin prévue 10/10 | F7: Refus : « La date de fin doit suivre la date de début. » | G7: Majeur | H7: OK | I7: Non testé
A8: PRJ-04 | B8: Engagé supérieur au budget | C8: INF (infrastructures@sygep.test) | D8: — | E8: 1. Budget 1 000 000, montant engagé 1 500 000 | F8: Une alerte rouge s'affiche en direct sous le champ ; à l'enregistrement : « Le montant engagé dépasse le budget prévu… ». | G8: Majeur | H8: OK | I8: Non testé
A9: PRJ-05 | B9: Ajouter des jalons | C9: INF (infrastructures@sygep.test) | D9: Un projet existe | E9: 1. Fiche du projet > Jalons : ajouter A (poids 1), B (poids 3) | F9: Les jalons apparaissent dans l'ordre. L'avancement reste 0 %. | G9: Critique | H9: OK | I9: Non testé
A10: PRJ-06 | B10: Avancement pondéré | C10: INF (infrastructures@sygep.test) | D10: Jalons A (1) et B (3) | E10: 1. Cocher le jalon B | F10: L'avancement passe à 75 % (3/4). Le projet « Planifié » devient « En cours ». | G10: Critique | H10: OK | I10: Non testé
A11: PRJ-07 | B11: Projet terminé automatiquement | C11: INF (infrastructures@sygep.test) | D11: — | E11: 1. Cocher aussi le jalon A | F11: L'avancement est 100 % ; le projet passe « Terminé ». | G11: Critique | H11: OK | I11: Non testé
A12: PRJ-08 | B12: Décocher un jalon | C12: INF (infrastructures@sygep.test) | D12: Projet terminé | E12: 1. Décocher le jalon A | F12: L'avancement redescend (75 %) et le projet repasse « En cours ». | G12: Majeur | H12: OK | I12: Non testé
A13: PRJ-09 | B13: Projet terminé sans jalon | C13: INF (infrastructures@sygep.test) | D13: — | E13: 1. Créer un projet « Terminé » avec date de démarrage, sans jalon, avancement laissé à 0 | F13: L'avancement enregistré est 100 %. | G13: Majeur | H13: OK | I13: Non testé
A14: PRJ-10 | B14: Avancement verrouillé | C14: INF (infrastructures@sygep.test) | D14: Projet avec jalons | E14: 1. Modifier le projet | F14: Le champ Avancement est désactivé avec la mention « calculé à partir des jalons ». | G14: Mineur | H14: OK | I14: Non testé
A15: PRJ-11 | B15: Projet en retard | C15: INF (infrastructures@sygep.test) | D15: Projet « En cours » dont la fin prévue est dépassée | E15: 1. Projets 2. Chiffres clés | F15: Il est compté en retard. | G15: Mineur | H15: OK | I15: Non testé
A16: PRJ-12 | B16: Ajouter un intervenant au projet | C16: INF (infrastructures@sygep.test) | D16: Un intervenant existe | E16: 1. Fiche du projet > Intervenants > Ajouter au projet | F16: L'intervenant apparaît dans la liste du projet. | G16: Majeur | H16: OK | I16: Non testé
... A24: PRJ-20 | B24: Rapport : date future ou sans projet | C24: INF (infrastructures@sygep.test) | D24: — | E24: 1. Date de demain, puis aucun projet | F24: Refus dans les deux cas. | G24: Mineur | H24: OK | I24: Non testé

Sheet MNT
A1: MNT – Demandes de maintenance (circuit complet)
A2: Vérifier chaque étape du circuit et ses effets sur les matières et infrastructures.
A4: ID | B4: Test | C4: Compte | D4: Préconditions | E4: Étapes | F4: Résultat attendu | G4: Priorité | H4: Pré-recette auto | I4: Résultat | J4: Date | K4: Testeur | L4: Observations
A5: MNT-01 | B5: Déposer une demande valide | C5: AGT (agent@sygep.test) | D5: Une matière du service existe | E5: 1. Demandes de maintenance > Ajouter 2. Objet, type Corrective, priorité Normale, Concerne « Matière », choisir la matière 3. Décrire le problème 4. Enregistrer | F5: La demande reçoit une référence DMT-AAAA-nnn au statut « Soumise ». Message « transmise pour validation ». | G5: Critique | H5: OK | I5: Non testé
A6: MNT-02 | B6: Description obligatoire | C6: AGT (agent@sygep.test) | D6: — | E6: 1. Déposer une demande sans description | F6: Refus : « Décrivez le problème (constat, localisation, depuis quand)… » | G6: Critique | H6: OK | I6: Non testé
A7: MNT-03 | B7: Cible infrastructure sans infrastructure | C7: AGT (agent@sygep.test) | D7: — | E7: 1. Concerne « Bâtiment / infrastructure », aucune infrastructure choisie | F7: Refus : « Choisissez l'infrastructure concernée. » | G7: Majeur | H7: OK | I7: Non testé
A8: MNT-04 | B8: Cible matière sans matière | C8: AGT (agent@sygep.test) | D8: — | E8: 1. Concerne « Matière / équipement », aucune matière choisie | F8: Refus : « Choisissez la matière concernée. » | G8: Majeur | H8: OK | I8: Non testé
A9: MNT-05 | B9: Notification au responsable | C9: MNT (maintenance@sygep.test) | D9: Demande MNT-01 déposée | E9: 1. Se connecter en MNT 2. Ouvrir la cloche | F9: Une notification « Nouvelle demande de maintenance … à valider » est présente, avec un lien vers la demande. | G9: Majeur | H9: OK | I9: Non testé
A10: MNT-06 | B10: Avis technique favorable | C10: MNT (maintenance@sygep.test) | D10: Demande « Soumise » | E10: 1. Ouvrir la demande 2. Bloc « Avis technique » > Valider | F10: Statut « Attente du Directeur ». Le Directeur reçoit une notification. | G10: Critique | H10: OK | I10: Non testé
A11: MNT-07 | B11: Rejet sans motif | C11: MNT (maintenance@sygep.test) | D11: Demande « Soumise » | E11: 1. Rejeter sans saisir de motif | F11: Refus : « Indiquez le motif du rejet. » | G11: Critique | H11: OK | I11: Non testé
A12: MNT-08 | B12: Rejet avec motif | C12: MNT (maintenance@sygep.test) | D12: Demande « Soumise » | E12: 1. Rejeter avec un motif | F12: Statut « Rejetée ». Le demandeur est notifié ; le motif est visible dans le suivi. | G12: Critique | H12: OK | I12: Non testé
A13: MNT-09 | B13: Approbation du Directeur | C13: DIR (directeur@sygep.test) | D13: Demande « Attente du Directeur » | E13: 1. Ouvrir la demande 2. Bloc « Approbation du Directeur » > Valider | F13: Statut « Approuvée ». Le responsable maintenance est notifié. | G13: Critique | H13: OK | I13: Non testé
A14: MNT-10 | B14: Le Directeur ne donne pas l'avis technique | C14: DIR (directeur@sygep.test) | D14: Demande « Soumise » | E14: 1. Ouvrir la demande | F14: Aucun bouton de décision n'est proposé (ou erreur 403 si l'action est forcée). | G14: Majeur | H14: OK | I14: Non testé
A15: MNT-11 | B15: Le responsable maintenance n'approuve pas | C15: MNT (maintenance@sygep.test) | D15: Demande « Attente du Directeur » | E15: 1. Ouvrir la demande | F15: Aucun bouton d'approbation n'est proposé. | G15: Majeur | H15: OK | I15: Non testé
A16: MNT-12 | B16: Planifier | C16: MNT (maintenance@sygep.test) | D16: Demande « Approuvée » | E16: 1. Bloc « Planifier » : date prévue, échéance, technicien, instructions 2. Enregistrer | F16: Statut « Planifiée ». Une tâche « [DMT-…] Objet » apparaît dans Tâches et dans le calendrier. Le technicien est notifié. | G16: Critique | H16: OK | I16: Non testé
... A27: MNT-23 | B27: Supprimer une demande | C27: ADM (admin@admin.com) | D27: Une demande de test | E27: 1. Supprimer la demande 2. Confirmer | F27: Elle disparaît de la liste. | G27: Mineur | H27: OK | I27: Non testé

Sheet PRV
A1: PRV – Maintenance préventive
A2: Vérifier la génération automatique des demandes d'entretien.
A4: ID | B4: Test | C4: Compte | D4: Préconditions | E4: Étapes | F4: Résultat attendu | G4: Priorité | H4: Pré-recette auto | I4: Résultat | J4: Date | K4: Testeur | L4: Observations
A5: PRV-01 | B5: Créer un plan valide | C5: MNT (maintenance@sygep.test) | D5: Une matière ou infrastructure | E5: 1. Maintenance préventive > Ajouter 2. Opération, cible, périodicité Semestrielle, échéance dans 20 jours, délai 7 jours, points de contrôle 3. Enregistrer | F5: Le plan apparaît, actif, avec sa prochaine échéance. | G5: Critique | H5: OK | I5: Non testé
A6: PRV-02 | B6: Points de contrôle obligatoires | C6: MNT (maintenance@sygep.test) | D6: — | E6: 1. Créer un plan sans points de contrôle | F6: Refus : « Listez les points de contrôle à vérifier à chaque opération. » | G6: Majeur | H6: OK | I6: Non testé
A7: PRV-03 | B7: Échéance dans le passé | C7: MNT (maintenance@sygep.test) | D7: — | E7: 1. Prochaine échéance = hier (à la création) | F7: Refus : « La prochaine échéance ne peut pas être dans le passé. » | G7: Majeur | H7: OK | I7: Non testé
A8: PRV-04 | B8: Délai supérieur à la périodicité | C8: MNT (maintenance@sygep.test) | D8: — | E8: 1. Périodicité Mensuelle, délai 45 jours | F8: Refus : « Le délai de création doit rester inférieur à la périodicité du plan. » | G8: Majeur | H8: OK | I8: Non testé
A9: PRV-05 | B9: Lancer un plan | C9: MNT (maintenance@sygep.test) | D9: Un plan actif | E9: 1. Cliquer ⚡ « Lancer » sur le plan | F9: Une demande préventive est créée au statut « Attente du Directeur » (avis technique déjà inscrit). Le Directeur et le responsable du plan sont notifiés. | G9: Critique | H9: OK | I9: Non testé
A10: PRV-06 | B10: Pas de doublon | C10: MNT (maintenance@sygep.test) | D10: Demande préventive déjà générée et encore ouverte | E10: 1. Cliquer de nouveau « Lancer » | F10: Aucune seconde demande n'est créée. | G10: Critique | H10: OK | I10: Non testé
A11: PRV-07 | B11: L'échéance avance | C11: MNT (maintenance@sygep.test) | D11: Plan lancé (PRV-05) | E11: 1. Consulter la prochaine échéance du plan | F11: Elle a avancé d'une période (+ 6 mois pour un plan semestriel). | G11: Majeur | H11: OK | I11: Non testé
A12: PRV-08 | B12: Commande automatique | C12: — | D12: Accès au serveur ; un plan dont la date « échéance − délai » est atteinte | E12: 1. Exécuter php artisan sygep:maintenance-preventive | F12: « n demande(s) préventive(s) créée(s) » ; sinon « Aucun entretien à programmer ». | G12: Critique | H12: OK | I12: Non testé
A13: PRV-09 | B13: Plan inactif | C13: MNT (maintenance@sygep.test) | D13: Un plan dont l'échéance est atteinte | E13: 1. Décocher « Plan actif » 2. Exécuter la commande ou cliquer Lancer | F13: Aucune demande n'est générée. | G13: Majeur | H13: OK | I13: Non testé
A14: PRV-10 | B14: Planificateur installé | C14: — | D14: Accès au serveur | E14: 1. Vérifier la présence de la ligne cron « schedule:run » ; observer le lendemain 6 h 30 | F14: Les plans échus génèrent leur demande sans intervention. | G14: Critique | H14: Manuel | I14: Non testé
A15: PRV-11 | B15: Clôture d'une demande préventive | C15: MNT (maintenance@sygep.test) | D15: Demande préventive approuvée puis exécutée | E15: 1. Clôturer l'intervention | F15: La « dernière réalisation » du plan est mise à la date du jour. | G15: Mineur | H15: OK | I15: Non testé

Sheet TCH
A1: TCH – Tâches, étiquettes et calendrier
A2: Vérifier l'organisation du travail des équipes.
A4: ID | B4: Test | C4: Compte | D4: Préconditions | E4: Étapes | F4: Résultat attendu | G4: Priorité | H4: Pré-recette auto | I4: Résultat | J4: Date | K4: Testeur | L4: Observations
A5: TCH-01 | B5: Créer une tâche valide | C5: MNT (maintenance@sygep.test) | D5: — | E5: 1. Tâches > Ajouter 2. Nom, état « Ouverte », date prévue 3. Enregistrer | F5: La tâche apparaît dans la liste et dans le calendrier. | G5: Critique | H5: OK | I5: Non testé
A6: TCH-02 | B6: Date limite avant la date prévue | C6: MNT (maintenance@sygep.test) | D6: — | E6: 1. Date prévue 20/10, date limite 10/10 | F6: Refus avec message sous la date limite. | G6: Majeur | H6: OK | I6: Non testé
A7: TCH-03 | B7: Statuts en français | C7: MNT (maintenance@sygep.test) | D7: — | E7: 1. Statuts des tâches | F7: Ouverte, En cours, Terminée sont présents. | G7: Critique | H7: OK | I7: Non testé
A8: TCH-04 | B8: Équipement affiché par nom et code | C8: MNT (maintenance@sygep.test) | D8: — | E8: 1. Tâches > Ajouter 2. Ouvrir la liste « Équipement » | F8: Chaque ligne affiche le nom suivi du code (et non un numéro de série éventuellement vide). | G8: Majeur | H8: OK | I8: Non testé
A9: TCH-05 | B9: Étiquettes | C9: MNT (maintenance@sygep.test) | D9: — | E9: 1. Étiquettes > Ajouter « Urgent » 2. L'associer à une tâche | F9: L'étiquette apparaît sur la tâche. | G9: Mineur | H9: OK | I9: Non testé
A10: TCH-06 | B10: Calendrier | C10: MNT (maintenance@sygep.test) | D10: Une tâche avec date limite et une sans date limite | E10: 1. Calendrier | F10: Les tâches qui ont une date limite apparaissent à cette date ; celle qui n'en a pas n'apparaît pas. | G10: Majeur | H10: OK | I10: Non testé
